Workbook

Sheet Cleaned Data
A1: order_id | B1: Product_category_cleaned | C1: origin_city | D1: destination_city.1 | E1: destination_state | F1: logistics_provider_name | G1: final_delivery_status | H1: Payment Mode | I1: Sources | J1: dispatch_date | K1: actual_delivery_date | L1: promised_delivery_date | M1: Delivery Days | N1: transit_storage_cost | O1: Helper_transit | P1: shipping_cost | Q1: Session_length
A2: 977567 | B2: Laptop | C2: Delhi | D2: Delhi | E2: DL | F2: FastWheels Ltd | G2: Delivered | H2: Credit Card | I2: App | J2: 43525.173 | K2: 43525.173 | L2: 43528.173 | M2: =_xlfn.DAYS(Table1[[#This Row],[actual_delivery_date]],Table1[[#This Row],[dispatch_date]]) -> 0 | N2: 0 | O2: =Table1[[#This Row],[transit_storage_cost]] * (1-'What -if Analysis'!$D$26) -> 0 | P2: 108 | Q2: 558.88768
A3: 703560 | B3: Mobile | C3: Delhi | D3: Delhi | E3: DL | F3: FastWheels Ltd | G3: Delivered | H3: Debit Card | I3: Website | J3: 43525.305 | K3: 43525.305 | L3: 43529.305 | M3: =_xlfn.DAYS(Table1[[#This Row],[actual_delivery_date]],Table1[[#This Row],[dispatch_date]]) -> 0 | N3: 0 | O3: =Table1[[#This Row],[transit_storage_cost]] * (1-'What -if Analysis'!$D$26) -> 0 | P3: 123 | Q3: 766
A4: 783549 | B4: Laptop | C4: Delhi | D4: Delhi | E4: DL | F4: FastWheels Ltd | G4: Returned | H4: Credit Card | I4: Website | J4: 43525.343 | K4: 43525.343 | L4: 43532.343 | M4: =_xlfn.DAYS(Table1[[#This Row],[actual_delivery_date]],Table1[[#This Row],[dispatch_date]]) -> 0 | N4: 0 | O4: =Table1[[#This Row],[transit_storage_cost]] * (1-'What -if Analysis'!$D$26) -> 0 | P4: 103 | Q4: 2763.7691
A5: 698253 | B5: Laptop | C5: Bangalore | D5: Bangalore | E5: KA | F5: FastWheels Ltd | G5: Delivered | H5: Credit Card | I5: Website | J5: 43525.388 | K5: 43525.388 | L5: 43530.388 | M5: =_xlfn.DAYS(Table1[[#This Row],[actual_delivery_date]],Table1[[#This Row],[dispatch_date]]) -> 0 | N5: 0 | O5: =Table1[[#This Row],[transit_storage_cost]] * (1-'What -if Analysis'!$D$26) -> 0 | P5: 108 | Q5: 2376.71
A6: 731550 | B6: Mobile | C6: Bangalore | D6: Bangalore | E6: KA | F6: FastWheels Ltd | G6: Delivered | H6: Debit Card | I6: Website | J6: 43525.388 | K6: 43525.388 | L6: 43532.388 | M6: =_xlfn.DAYS(Table1[[#This Row],[actual_delivery_date]],Table1[[#This Row],[dispatch_date]]) -> 0 | N6: 0 | O6: =Table1[[#This Row],[transit_storage_cost]] * (1-'What -if Analysis'!$D$26) -> 0 | P6: 108 | Q6: 1684.43
A7: 421910 | B7: Laptop | C7: Delhi | D7: Delhi | E7: DL | F7: FastWheels Ltd | G7: Delivered | H7: Debit Card | I7: App | J7: 43525.425 | K7: 43525.425 | L7: 43528.425 | M7: =_xlfn.DAYS(Table1[[#This Row],[actual_delivery_date]],Table1[[#This Row],[dispatch_date]]) -> 0 | N7: 0 | O7: =Table1[[#This Row],[transit_storage_cost]] * (1-'What -if Analysis'!$D$26) -> 0 | P7: 108 | Q7: 2478.4656
A8: 526095 | B8: Mobile | C8: Delhi | D8: Delhi | E8: DL | F8: FastWheels Ltd | G8: Delivered | H8: Credit Card | I8: Website | J8: 43525.454 | K8: 43525.454 | L8: 43530.454 | M8: =_xlfn.DAYS(Table1[[#This Row],[actual_delivery_date]],Table1[[#This Row],[dispatch_date]]) -> 0 | N8: 0 | O8: =Table1[[#This Row],[transit_storage_cost]] * (1-'What -if Analysis'!$D$26) -> 0 | P8: 104 | Q8: 3387.3
A9: 469838 | B9: Mobile | C9: Bangalore | D9: Bangalore | E9: KA | F9: Ship2Home Logistics Unit | G9: Delivered | H9: Debit Card | I9: App | J9: 43525.455 | K9: 43525.455 | L9: 43532.455 | M9: =_xlfn.DAYS(Table1[[#This Row],[actual_delivery_date]],Table1[[#This Row],[dispatch_date]]) -> 0 | N9: 0 | O9: =Table1[[#This Row],[transit_storage_cost]] * (1-'What -if Analysis'!$D$26) -> 0 | P9: 130 | Q9: 3461.6871
A10: 208180 | B10: Mobile | C10: Bangalore | D10: Bangalore | E10: KA | F10: FastWheels Ltd | G10: Delivered | H10: Debit Card | I10: App | J10: 43525.747 | K10: 43525.747 | L10: 43531.747 | M10: =_xlfn.DAYS(Table1[[#This Row],[actual_delivery_date]],Table1[[#This Row],[dispatch_date]]) -> 0 | N10: 0 | O10: =Table1[[#This Row],[transit_storage_cost]] * (1-'What -if Analysis'!$D$26) -> 0 | P10: 125 | Q10: 2910.9519
A11: 253533 | B11: Mobile | C11: Bangalore | D11: Bangalore | E11: KA | F11: FastWheels Ltd | G11: Delivered | H11: Cash On Delivery | I11: Website | J11: 43525.866 | K11: 43525.866 | L11: 43531.866 | M11: =_xlfn.DAYS(Table1[[#This Row],[actual_delivery_date]],Table1[[#This Row],[dispatch_date]]) -> 0 | N11: 0 | O11: =Table1[[#This Row],[transit_storage_cost]] * (1-'What -if Analysis'!$D$26) -> 0 | P11: 101 | Q11: 3254.26
A12: 379572 | B12: PC | C12: Delhi | D12: Delhi | E12: DL | F12: FastWheels Ltd | G12: Delivered | H12: Debit Card | I12: Website | J12: 43526.047 | K12: 43526.047 | L12: 43529.047 | M12: =_xlfn.DAYS(Table1[[#This Row],[actual_delivery_date]],Table1[[#This Row],[dispatch_date]]) -> 0 | N12: 0 | O12: =Table1[[#This Row],[transit_storage_cost]] * (1-'What -if Analysis'!$D$26) -> 0 | P12: 101 | Q12: 2133.03
A13: 438274 | B13: Laptop | C13: Bangalore | D13: Bangalore | E13: KA | F13: Ship2Home Logistics Unit | G13: Delivered | H13: Debit Card | I13: App | J13: 43525.055 | K13: 43526.055 | L13: 43531.055 | M13: =_xlfn.DAYS(Table1[[#This Row],[actual_delivery_date]],Table1[[#This Row],[dispatch_date]]) -> 1 | N13: 0 | O13: =Table1[[#This Row],[transit_storage_cost]] * (1-'What -if Analysis'!$D$26) -> 0 | P13: 122 | Q13: 1547.3549
... A161: 463167 | B161: Tablet | C161: Delhi | D161: Bangalore | E161: KA | F161: FastWheels Ltd | G161: Delivered | H161: Credit Card | I161: Website | J161: 43526.498 | K161: 43528.498 | L161: 43531.498 | M161: =_xlfn.DAYS(Table1[[#This Row],[actual_delivery_date]],Table1[[#This Row],[dispatch_date]]) -> 2 | N161: 64 | O161: =Table1[[#This Row],[transit_storage_cost]] * (1-'What -if Analysis'!$D$26) -> 64 | P161: 105 | Q161: 3591.7
A162: 834190 | B162: Laptop | C162: Delhi | D162: Bangalore | E162: KA | G162: Delivered | H162: Debit Card | I162: App | J162: 43526.5 | K162: 43528.5 | L162: 43533.5 | M162: =_xlfn.DAYS(Table1[[#This Row],[actual_delivery_date]],Table1[[#This Row],[dispatch_date]]) -> 2 | N162: 31 | O162: =Table1[[#This Row],[transit_storage_cost]] * (1-'What -if Analysis'!$D$26) -> 31 | P162: 128 | Q162: 3311.7521
A163: 836756 | B163: PC | C163: Bangalore | D163: Kolkata | E163: WB | F163: FastWheels Ltd | G163: Delivered | H163: Debit Card | I163: App | J163: 43525.501 | K163: 43528.501 | L163: 43531.501 | M163: =_xlfn.DAYS(Table1[[#This Row],[actual_delivery_date]],Table1[[#This Row],[dispatch_date]]) -> 3 | N163: 26 | O163: =Table1[[#This Row],[transit_storage_cost]] * (1-'What -if Analysis'!$D$26) -> 26 | P163: 115 | Q163: 586.91424
A164: 473212 | B164: Laptop | C164: Delhi | D164: Delhi | E164: DL | F164: FastWheels Ltd | G164: Delivered | H164: Debit Card | I164: App | J164: 43525.504 | K164: 43528.504 | L164: 43528.504 | M164: =_xlfn.DAYS(Table1[[#This Row],[actual_delivery_date]],Table1[[#This Row],[dispatch_date]]) -> 3 | N164: 0 | O164: =Table1[[#This Row],[transit_storage_cost]] * (1-'What -if Analysis'!$D$26) -> 0 | P164: 126 | Q164: 3113.819
A165: 260810 | B165: Gaming Console | C165: Delhi | D165: Mumbai | E165: MH | F165: FastWheels Ltd | G165: Delivered | H165: Debit Card | I165: App | J165: 43526.508 | K165: 43528.508 | L165: 43531.508 | M165: =_xlfn.DAYS(Table1[[#This Row],[actual_delivery_date]],Table1[[#This Row],[dispatch_date]]) -> 2 | N165: 71 | O165: =Table1[[#This Row],[transit_storage_cost]] * (1-'What -if Analysis'!$D$26) -> 71 | P165: 92 | Q165: 2600.7327
A166: 276378 | B166: Mobile | C166: Bangalore | D166: Mumbai | E166: MH | F166: FastWheels Ltd | G166: Delivered | H166: Debit Card | I166: Website | J166: 43526.517 | K166: 43528.517 | L166: 43532.517 | M166: =_xlfn.DAYS(Table1[[#This Row],[actual_delivery_date]],Table1[[#This Row],[dispatch_date]]) -> 2 | N166: 71 | O166: =Table1[[#This Row],[transit_storage_cost]] * (1-'What -if Analysis'!$D$26) -> 71 | P166: 94 | Q166: 1334.86
A167: 11940 | B167: Mobile | C167: Delhi | D167: Bangalore | E167: KA | F167: FastWheels Ltd | G167: Delivered | H167: Debit Card | I167: Website | J167: 43526.526 | K167: 43528.526 | L167: 43530.526 | M167: =_xlfn.DAYS(Table1[[#This Row],[actual_delivery_date]],Table1[[#This Row],[dispatch_date]]) -> 2 | N167: 40 | O167: =Table1[[#This Row],[transit_storage_cost]] * (1-'What -if Analysis'!$D$26) -> 40 | P167: 125 | Q167: 1802.29
A168: 601672 | B168: Tablet | C168: Delhi | D168: Kolkata | E168: WB | F168: FastWheels Ltd | G168: Delivered | H168: Debit Card | I168: App | J168: 43525.533 | K168: 43528.533 | L168: 43530.533 | M168: =_xlfn.DAYS(Table1[[#This Row],[actual_delivery_date]],Table1[[#This Row],[dispatch_date]]) -> 3 | N168: 28 | O168: =Table1[[#This Row],[transit_storage_cost]] * (1-'What -if Analysis'!$D$26) -> 28 | P168: 106 | Q168: 990.00048
A169: 707752 | B169: Tablet | C169: Delhi | D169: Mumbai | E169: MH | F169: FastWheels Ltd | G169: Delivered | H169: Debit Card | I169: App | J169: 43525.549 | K169: 43528.549 | L169: 43529.549 | M169: =_xlfn.DAYS(Table1[[#This Row],[actual_delivery_date]],Table1[[#This Row],[dispatch_date]]) -> 3 | N169: 86 | O169: =Table1[[#This Row],[transit_storage_cost]] * (1-'What -if Analysis'!$D$26) -> 86 | P169: 86 | Q169: 3517.3202
A170: 655078 | B170: Mobile | C170: Bangalore | D170: Kolkata | E170: WB | F170: Ship2Home Logistics Unit | G170: Delivered | H170: Debit Card | I170: App | J170: 43526.55 | K170: 43528.55 | L170: 43529.55 | M170: =_xlfn.DAYS(Table1[[#This Row],[actual_delivery_date]],Table1[[#This Row],[dispatch_date]]) -> 2 | N170: 39 | O170: =Table1[[#This Row],[transit_storage_cost]] * (1-'What -if Analysis'!$D$26) -> 39 | P170: 108 | Q170: 2939.1285
A171: 62892 | B171: Laptop | C171: Bangalore | D171: Mumbai | E171: MH | F171: FastWheels Ltd | G171: Delivered | H171: Debit Card | I171: Website | J171: 43526.559 | K171: 43528.559 | L171: 43532.559 | M171: =_xlfn.DAYS(Table1[[#This Row],[actual_delivery_date]],Table1[[#This Row],[dispatch_date]]) -> 2 | N171: 70 | O171: =Table1[[#This Row],[transit_storage_cost]] * (1-'What -if Analysis'!$D$26) -> 70 | P171: 95 | Q171: 2826.98
A172: 13342 | B172: Tablet | C172: Bangalore | D172: Delhi | E172: DL | F172: FastWheels Ltd | G172: Delivered | H172: Debit Card | I172: App | J172: 43526.564 | K172: 43528.564 | L172: 43529.564 | M172: =_xlfn.DAYS(Table1[[#This Row],[actual_delivery_date]],Table1[[#This Row],[dispatch_date]]) -> 2 | N172: 67 | O172: =Table1[[#This Row],[transit_storage_cost]] * (1-'What -if Analysis'!$D$26) -> 67 | P172: 106 | Q172: 3656.1546
A173: 319442 | B173: Mobile | C173: Bangalore | D173: Chennai | E173: TN | F173: Ship2Home Logistics Unit | G173: Returned | H173: Debit Card | I173: App | J173: 43526.603 | K173: 43528.603 | L173: 43532.603 | M173: =_xlfn.DAYS(Table1[[#This Row],[actual_delivery_date]],Table1[[#This Row],[dispatch_date]]) -> 2 | N173: 31 | O173: =Table1[[#This Row],[transit_storage_cost]] * (1-'What -if Analysis'!$D$26) -> 31 | P173: 128 | Q173: 3456.4382
A174: 519269 | B174: TV | C174: Delhi | D174: Delhi | E174: DL | F174: Ship2Home delivery | G174: Delivered | H174: Credit Card | I174: App | J174: 43525.618 | K174: 43528.618 | L174: 43530.618 | M174: =_xlfn.DAYS(Table1[[#This Row],[actual_delivery_date]],Table1[[#This Row],[dispatch_date]]) -> 3 | N174: 0 | O174: =Table1[[#This Row],[transit_storage_cost]] * (1-'What -if Analysis'!$D$26) -> 0 | P174: 126 | Q174: 417.20076
... A934: 454739 | B934: PC | C934: Bangalore | D934: Delhi | E934: DL | F934: Ship2Home delivery | G934: Delivered | H934: Credit Card | I934: App | J934: 43528.312 | K934: 43532.312 | L934: 43531.312 | M934: =_xlfn.DAYS(Table1[[#This Row],[actual_delivery_date]],Table1[[#This Row],[dispatch_date]]) -> 4 | N934: 35 | O934: =Table1[[#This Row],[transit_storage_cost]] * (1-'What -if Analysis'!$D$26) -> 35 | P934: 125 | Q934: 1804.7607
A935: 543275 | B935: TV | C935: Delhi | D935: Mumbai | E935: MH | G935: Delivered | H935: Credit Card | I935: App | J935: 43530.318 | K935: 43532.318 | L935: 43536.318 | M935: =_xlfn.DAYS(Table1[[#This Row],[actual_delivery_date]],Table1[[#This Row],[dispatch_date]]) -> 2 | N935: 49 | O935: =Table1[[#This Row],[transit_storage_cost]] * (1-'What -if Analysis'!$D$26) -> 49 | P935: 111 | Q935: 2312.745
A936: 58385 | B936: Tablet | C936: Delhi | D936: Chennai | E936: TN | F936: Ship2Home delivery | G936: Delivered | H936: Credit Card | I936: App | J936: 43526.321 | K936: 43532.321 | L936: 43531.321 | M936: =_xlfn.DAYS(Table1[[#This Row],[actual_delivery_date]],Table1[[#This Row],[dispatch_date]]) -> 6 | N936: 40 | O936: =Table1[[#This Row],[transit_storage_cost]] * (1-'What -if Analysis'!$D$26) -> 40 | P936: 123 | Q936: 3002.8836
A937: 458152 | B937: PC | C937: Delhi | D937: Chennai | E937: TN | F937: FastWheels Ltd | G937: Delivered | H937: Debit Card | I937: App | J937: 43525.326 | K937: 43532.326 | L937: 43531.326 | M937: =_xlfn.DAYS(Table1[[#This Row],[actual_delivery_date]],Table1[[#This Row],[dispatch_date]]) -> 7 | N937: 41 | O937: =Table1[[#This Row],[transit_storage_cost]] * (1-'What -if Analysis'!$D$26) -> 41 | P937: 127 | Q937: 3365.0038
A938: 904751 | B938: Laptop | C938: Bangalore | D938: Kolkata | E938: WB | F938: FastWheels Ltd | G938: Delivered | H938: Credit Card | I938: App | J938: 43527.327 | K938: 43532.327 | L938: 43533.327 | M938: =_xlfn.DAYS(Table1[[#This Row],[actual_delivery_date]],Table1[[#This Row],[dispatch_date]]) -> 5 | N938: 65 | O938: =Table1[[#This Row],[transit_storage_cost]] * (1-'What -if Analysis'!$D$26) -> 65 | P938: 89 | Q938: 1011.3207
A939: 127447 | B939: Tablet | C939: Delhi | D939: Delhi | E939: DL | F939: Ship2Home delivery | G939: Delivered | H939: Credit Card | I939: App | J939: 43530.336 | K939: 43532.336 | L939: 43537.336 | M939: =_xlfn.DAYS(Table1[[#This Row],[actual_delivery_date]],Table1[[#This Row],[dispatch_date]]) -> 2 | N939: 0 | O939: =Table1[[#This Row],[transit_storage_cost]] * (1-'What -if Analysis'!$D$26) -> 0 | P939: 128 | Q939: 1440.33
A940: 143957 | B940: PC | C940: Delhi | D940: Delhi | E940: DL | F940: Ship2Home delivery | G940: Delivered | H940: Credit Card | I940: App | J940: 43526.34 | K940: 43532.34 | L940: 43529.34 | M940: =_xlfn.DAYS(Table1[[#This Row],[actual_delivery_date]],Table1[[#This Row],[dispatch_date]]) -> 6 | N940: 0 | O940: =Table1[[#This Row],[transit_storage_cost]] * (1-'What -if Analysis'!$D$26) -> 0 | P940: 124 | Q940: 2165.7016
A941: 453223 | B941: TV | C941: Delhi | D941: Kolkata | E941: WB | F941: Ship2Home delivery | G941: Delivered | H941: Credit Card | I941: App | J941: 43527.345 | K941: 43532.345 | L941: 43532.345 | M941: =_xlfn.DAYS(Table1[[#This Row],[actual_delivery_date]],Table1[[#This Row],[dispatch_date]]) -> 5 | N941: 40 | O941: =Table1[[#This Row],[transit_storage_cost]] * (1-'What -if Analysis'!$D$26) -> 40 | P941: 106 | Q941: 3325.0129
A942: 125497 | B942: PC | C942: Bangalore | D942: Delhi | E942: DL | F942: Ship2Home delivery | G942: Delivered | H942: Credit Card | I942: App | J942: 43525.345 | K942: 43532.345 | L942: 43528.345 | M942: =_xlfn.DAYS(Table1[[#This Row],[actual_delivery_date]],Table1[[#This Row],[dispatch_date]]) -> 7 | N942: 27 | O942: =Table1[[#This Row],[transit_storage_cost]] * (1-'What -if Analysis'!$D$26) -> 27 | P942: 125 | Q942: 787.72129
A943: 64570 | B943: Laptop | C943: Bangalore | D943: Bangalore | E943: KA | F943: FastWheels Ltd | G943: Delivered | H943: Debit Card | I943: App | J943: 43528.348 | K943: 43532.348 | L943: 43534.348 | M943: =_xlfn.DAYS(Table1[[#This Row],[actual_delivery_date]],Table1[[#This Row],[dispatch_date]]) -> 4 | N943: 0 | O943: =Table1[[#This Row],[transit_storage_cost]] * (1-'What -if Analysis'!$D$26) -> 0 | P943: 103 | Q943: 1762.699
A944: 854355 | B944: Mobile | C944: Delhi | D944: Bangalore | E944: KA | F944: FastWheels Ltd | G944: Delivered | H944: Credit Card | I944: Website | J944: 43530.349 | K944: 43532.349 | L944: 43537.349 | M944: =_xlfn.DAYS(Table1[[#This Row],[actual_delivery_date]],Table1[[#This Row],[dispatch_date]]) -> 2 | N944: 61 | O944: =Table1[[#This Row],[transit_storage_cost]] * (1-'What -if Analysis'!$D$26) -> 61 | P944: 109 | Q944: 3717.8135
A945: 101282 | B945: TV | C945: Delhi | D945: Kolkata | E945: WB | F945: Ship2Home Logistics Unit | G945: Delivered | H945: Debit Card | I945: App | J945: 43527.35 | K945: 43532.35 | L945: 43533.35 | M945: =_xlfn.DAYS(Table1[[#This Row],[actual_delivery_date]],Table1[[#This Row],[dispatch_date]]) -> 5 | N945: 31 | O945: =Table1[[#This Row],[transit_storage_cost]] * (1-'What -if Analysis'!$D$26) -> 31 | P945: 107 | Q945: 2948.1301
A946: 478547 | B946: Mobile | C946: Delhi | D946: Delhi | E946: DL | F946: FastWheels Ltd | G946: Delivered | H946: Credit Card | I946: App | J946: 43527.351 | K946: 43532.351 | L946: 43533.351 | M946: =_xlfn.DAYS(Table1[[#This Row],[actual_delivery_date]],Table1[[#This Row],[dispatch_date]]) -> 5 | N946: 0 | O946: =Table1[[#This Row],[transit_storage_cost]] * (1-'What -if Analysis'!$D$26) -> 0 | P946: 109 | Q946: 2465.473
...

Sheet Data Understanding

Sheet Descriptive Statistics
D10: Metrics | E10: Delivery Days | F10: transit_storage_cost | G10: shipping_cost | H10: Session_length
D11: Median | E11: =MEDIAN(Table1[Delivery Days]) -> 4 | F11: =MEDIAN(Table1[transit_storage_cost]) -> 37 | G11: =MEDIAN(Table1[shipping_cost]) -> 112 | H11: =MEDIAN(Table1[Session_length]) -> 1988.4188
D12: Average | E12: =AVERAGE(Table1[Delivery Days]) -> 4.5701652 | F12: =AVERAGE(Table1[transit_storage_cost]) -> 87.286712 | G12: =AVERAGE(Table1[shipping_cost]) -> 113.29788 | H12: =AVERAGE(Table1[Session_length]) -> 1990.0856
D13: Minimum | E13: =MIN(Table1[Delivery Days]) -> 0 | F13: =MIN(Table1[transit_storage_cost]) -> 0 | G13: =MIN(Table1[shipping_cost]) -> 85 | H13: =MIN(Table1[Session_length]) -> -1
D14: Maximum | E14: =MAX(Table1[Delivery Days]) -> 11 | F14: =MAX(Table1[transit_storage_cost]) -> 9999 | G14: =MAX(Table1[shipping_cost]) -> 130 | H14: =MAX(Table1[Session_length]) -> 3877.9825
D15: St.Dev | E15: =_xlfn.STDEV.P(Table1[Delivery Days]) -> 2.4336241 | F15: =_xlfn.STDEV.P(Table1[transit_storage_cost]) -> 711.48314 | G15: =_xlfn.STDEV.P(Table1[shipping_cost]) -> 11.896524 | H15: =_xlfn.STDEV.P(Table1[Session_length]) -> 1005.8906
D16: Variane | E16: =_xlfn.VAR.P(Table1[Delivery Days]) -> 5.9225262 | F16: =_xlfn.VAR.P(Table1[transit_storage_cost]) -> 506208.26 | G16: =_xlfn.VAR.P(Table1[shipping_cost]) -> 141.52728 | H16: =_xlfn.VAR.P(Table1[Session_length]) -> 1011815.9
D17: Count | E17: =COUNT(Table1[Delivery Days]) -> 4297 | F17: =COUNT(Table1[transit_storage_cost]) -> 4297 | G17: =COUNT(Table1[shipping_cost]) -> 4297 | H17: =COUNT(Table1[Session_length]) -> 4297
D18: Skewness | E18: =SKEW(Table1[Delivery Days]) -> 0.25308484 | F18: =SKEW(Table1[transit_storage_cost]) -> 13.846545 | G18: =SKEW(Table1[shipping_cost]) -> -0.4900254 | H18: =SKEW(Table1[Session_length]) -> 0.0076774036

Sheet Pivot Table Analysis
B9: Product Category | C9: Average of shipping_cost | E9: Product Category | F9: Count of order_id
B10: Gaming Console | C10: 113.61377 | E10: Gaming Console | F10: 334
B11: Laptop | C11: 113.00875 | E11: Laptop | F11: 1029
B12: Mobile | C12: 112.97994 | E12: Mobile | F12: 1246
B13: PC | C13: 113.80267 | E13: PC | F13: 674
B14: Tablet | C14: 113.64017 | E14: Tablet | F14: 478
B15: TV | C15: 113.36106 | E15: TV | F15: 529
B16: Grand Total | C16: 113.28601 | E16: Grand Total | F16: 4290
B23: final_delivery_status | C23: Delivered | E23: final_delivery_status | F23: Delivered
B25: Logistics Provider | C25: Average of Delivery Days | E25: Logistics Provider | F25: Count of order_id
B26: FastWheels Ltd | C26: 4.035288 | E26: FastWheels Ltd | F26: 1927
B27: Ship2Home delivery | C27: 5.0809555 | E27: Ship2Home delivery | F27: 1507
B28: Ship2Home Logistics Unit | C28: 4.9690027 | E28: Ship2Home Logistics Unit | F28: 742
B29: Grand Total | C29: 4.5785441 | E29: Grand Total | F29: 4176
B39: Count of order_id | C39: Sources
B40: Payment Mode | C40: Cash On Delivery | D40: Credit Card | E40: Debit Card | F40: Grand Total
B41: App | C41: 197 | D41: 1228 | E41: 1441 | F41: 2866
B42: Website | C42: 121 | D42: 590 | E42: 713 | F42: 1424
B43: Grand Total | C43: 318 | D43: 1818 | E43: 2154 | F43: 4290
B52: Destination City | C52: Average of shipping_cost | D52: Average of transit_storage_cost | F52: Destination City | G52: Count of order_id
B53: Bangalore | C53: 119.04357 | D53: 82.617647 | F53: Bangalore | G53: 918
B54: Chennai | C54: 119.73239 | D54: 63.746479 | F54: Chennai | G54: 568
B55: Delhi | C55: 118.97124 | D55: 94.584416 | F55: Delhi | G55: 1078
B56: Kolkata | C56: 104.58947 | D56: 98.982456 | F56: Kolkata | G56: 570
B57: Mumbai | C57: 104.53287 | D57: 90.314879 | F57: Mumbai | G57: 1156
B58: Grand Total | C58: 113.28601 | D58: 87.374592 | F58: Grand Total | G58: 4290
B66: Delivery Days | C66: Count of order_id | D66: Average of Session_length
B67: 0 | C67: 165 | D67: 2076.2795
B68: 1 | C68: 148 | D68: 1828.3905
B69: 2 | C69: 746 | D69: 1958.1725
B70: 3 | C70: 513 | D70: 1970.9796
B71: 4 | C71: 585 | D71: 2017.1097
B72: 5 | C72: 613 | D72: 2040.8704
B73: 6 | C73: 563 | D73: 1981.6907
B74: 7 | C74: 420 | D74: 1996.2255
B75: 8 | C75: 232 | D75: 2018.6251
B76: 9 | C76: 202 | D76: 1962.2606
B77: 10 | C77: 85 | D77: 1893.9336
B78: 11 | C78: 18 | D78: 2173.2961
B79: Grand Total | C79: 4290 | D79: 1989.5263

Sheet What -if Analysis
C13: Shipping Cost Increase % | D13: Shipping Cost
C14: 0 | D14: =AVERAGE(Table1[shipping_cost])*(1+C14) -> 113.29788
C15: 0.05 | D15: 118.96278
C16: 0.1 | D16: 124.62767
C17: 0.15 | D17: 130.29256
C24: Transit Storage Cost | D24: 28
C25: Improved Transit Storage Cost | D25: =$D$24*(1-D26) -> 28
C26: Storage Reduction | D26: 0
C32: Average Delivery Days | D32: =AVERAGE(Table1[Delivery Days]) -> 4.5701652
C33: Average Session length | D33: =AVERAGE(Table1[Session_length]) -> 1990.0856
C34: Delivery Impact Factor | D34: -335544.32
C35: Improved Session Length | D35: =D33*(1+D34) -> -6.6775993e+08
C36: Target Delivery Days | D36: =D32-2 -> 2.5701652

Sheet Scenario Summary
B2: Scenario Summary
D3: Current Values: | E3: Optimized
E4: Created by Sarthak Somani on 08-01-2026 Modified by Sarthak Somani on 08-01-2026
B5: Changing Cells:
C6: $D$21 | D6: 0 | E6: 0.2
B7: Result Cells:
C8: $D$20 | D8: 28 | E8: 22.4
B9: Notes: Current Values column represents values of changing cells at
B10: time Scenario Summary Report was created. Changing cells for each
B11: scenario are highlighted in gray.

Sheet Data Visualization 

Sheet Forecast
A1: Delivery Days | B1: shipping_cost | C1: Forecast(shipping_cost) | D1: Lower Confidence Bound(shipping_cost) | E1: Upper Confidence Bound(shipping_cost)
A2: 0 | B2: 114.1697
A3: 1 | B3: 118.70946
A4: 2 | B4: 110.45551
A5: 3 | B5: 113.02144
A6: 4 | B6: 113.05128
A7: 5 | B7: 113.12561
A8: 6 | B8: 113.80639
A9: 7 | B9: 114.38095
A10: 8 | B10: 113.81034
A11: 9 | B11: 114.53465
A12: 10 | B12: 118.77647
A13: 11 | B13: 113.94444 | C13: 113.94444 | D13: 113.94444 | E13: 113.94444
A14: 12 | C14: =_xlfn.FORECAST.ETS(A14,$B$2:$B$13,$A$2:$A$13,1,1) -> 115.63369 | D14: =C14-_xlfn.FORECAST.ETS.CONFINT(A14,$B$2:$B$13,$A$2:$A$13,0.95,1,1) -> 112.07779 | E14: =C14+_xlfn.FORECAST.ETS.CONFINT(A14,$B$2:$B$13,$A$2:$A$13,0.95,1,1) -> 119.18959
A15: 13 | C15: =_xlfn.FORECAST.ETS(A15,$B$2:$B$13,$A$2:$A$13,1,1) -> 117.99768 | D15: =C15-_xlfn.FORECAST.ETS.CONFINT(A15,$B$2:$B$13,$A$2:$A$13,0.95,1,1) -> 114.41322 | E15: =C15+_xlfn.FORECAST.ETS.CONFINT(A15,$B$2:$B$13,$A$2:$A$13,0.95,1,1) -> 121.58215
A16: 14 | C16: =_xlfn.FORECAST.ETS(A16,$B$2:$B$13,$A$2:$A$13,1,1) -> 113.96908 | D16: =C16-_xlfn.FORECAST.ETS.CONFINT(A16,$B$2:$B$13,$A$2:$A$13,0.95,1,1) -> 110.35583 | E16: =C16+_xlfn.FORECAST.ETS.CONFINT(A16,$B$2:$B$13,$A$2:$A$13,0.95,1,1) -> 117.58233
A17: 15 | C17: =_xlfn.FORECAST.ETS(A17,$B$2:$B$13,$A$2:$A$13,1,1) -> 116.15789 | D17: =C17-_xlfn.FORECAST.ETS.CONFINT(A17,$B$2:$B$13,$A$2:$A$13,0.95,1,1) -> 112.51519 | E17: =C17+_xlfn.FORECAST.ETS.CONFINT(A17,$B$2:$B$13,$A$2:$A$13,0.95,1,1) -> 119.80059
A18: 16 | C18: =_xlfn.FORECAST.ETS(A18,$B$2:$B$13,$A$2:$A$13,1,1) -> 118.52188 | D18: =C18-_xlfn.FORECAST.ETS.CONFINT(A18,$B$2:$B$13,$A$2:$A$13,0.95,1,1) -> 114.84997 | E18: =C18+_xlfn.FORECAST.ETS.CONFINT(A18,$B$2:$B$13,$A$2:$A$13,0.95,1,1) -> 122.1938
A19: 17 | C19: =_xlfn.FORECAST.ETS(A19,$B$2:$B$13,$A$2:$A$13,1,1) -> 114.49328 | D19: =C19-_xlfn.FORECAST.ETS.CONFINT(A19,$B$2:$B$13,$A$2:$A$13,0.95,1,1) -> 110.79194 | E19: =C19+_xlfn.FORECAST.ETS.CONFINT(A19,$B$2:$B$13,$A$2:$A$13,0.95,1,1) -> 118.19462

Sheet Dashboard 
F9: KPI's | G9: Values
B10: Average Delivery Days | F10: Average Delivery Days | G10: =AVERAGE(Table1[Delivery Days]) -> 4.5701652 | I10: Average Shipping Cost
F11: Average Shipping Cost | G11: =AVERAGE(Table1[shipping_cost]) -> 113.29788
F12: Average Transit Cost | G12: =AVERAGE(Table1[transit_storage_cost]) -> 87.286712
F13: Average Session Length | G13: =AVERAGE(Table1[Session_length]) -> 1990.0856
F14: Highest Transit Cost | G14: =MAX(Table1[transit_storage_cost]) -> 9999
F15: Max Shipping Days | G15: =MAX(Table1[Delivery Days]) -> 11
F16: Highest Shipping Cost | G16: =MAX(Table1[shipping_cost]) -> 130
B18: Average Transit Cost | I18: Average Session length
F23: Highest Shipping Cost
B25: Highest Transit Cost | I25: Max Shipping Days

Sheet Insights
